<sdf  version="1.7">
    
    
    
    <!-- Constants for robot dimensions -->
    
    
     
     
     <!-- Link 2 -->
     <!-- Link 3 -->
     <!-- Size of square 'camera' box -->
     <!-- Space btw top of beam and the each joint -->

    <model name="rrbot">
        <pose>0 0 0 0 0 0</pose>
        <link name="heavy_base">
            <pose>0 0 0.05 0 0 0</pose>
            <inertial>
                
            <mass>100.0</mass><inertia>
            <ixx>8.416666666666666</ixx>
            <ixy>0</ixy>
            <ixz>0</ixz>
            <iyy>8.416666666666666</iyy>
            <iyz>0</iyz>
            <izz>16.666666666666668</izz>
        </inertia></inertial>
            
        <collision name="heavy_base_collision">
            
        <geometry>
            <box>
                <size>1.0 1.0 0.1</size>
            </box>
        </geometry></collision><visual name="heavy_base_visual">
            
            <material>
                
            <lighting>1</lighting><script>
            <uri>file://media/materials/scripts/gazebo.material</uri>
            <name>Gazebo/Black</name>
        </script></material>
        <geometry>
            <box>
                <size>1.0 1.0 0.1</size>
            </box>
        </geometry></visual></link>
        <joint name="rrbot_to_heavy_base" type="fixed">
            <parent>heavy_base</parent>
            <child>link1</child>
        </joint>
        <link name="link1">
            <pose relative_to="heavy_base">0 0 1.05 0 0 0</pose>
            <inertial>
                
            <mass>1.0</mass><inertia>
            <ixx>0.33416666666666667</ixx>
            <ixy>0</ixy>
            <ixz>0</ixz>
            <iyy>0.33416666666666667</iyy>
            <iyz>0</iyz>
            <izz>0.001666666666666667</izz>
        </inertia></inertial>
            
        <collision name="link1_collision">
            
        <geometry>
            <box>
                <size>0.1 0.1 2.0</size>
            </box>
        </geometry></collision><visual name="link1_visual">
            
            <material>
                
            <lighting>1</lighting><script>
            <uri>file://media/materials/scripts/gazebo.material</uri>
            <name>Gazebo/Orange</name>
        </script></material>
        <geometry>
            <box>
                <size>0.1 0.1 2.0</size>
            </box>
        </geometry></visual></link>
        <joint name="joint1" type="revolute">
            <parent>link1</parent>
            <child>link2</child>
            <pose>0 0 0.45 0 0 0</pose>
            <axis>
                <xyz>1 0 0</xyz>
                <dynamics>
                    <damping>0.5</damping>
                  </dynamics>
            </axis>
        </joint>
        <link name="link2">
            <pose relative_to="link1">0.1 0 0.45 0 0 0</pose>
            <inertial>
                
            <mass>1.0</mass><inertia>
            <ixx>0.08416666666666667</ixx>
            <ixy>0</ixy>
            <ixz>0</ixz>
            <iyy>0.08416666666666667</iyy>
            <iyz>0</iyz>
            <izz>0.001666666666666667</izz>
        </inertia></inertial>
            
        <collision name="link2_collision">
            
        <geometry>
            <box>
                <size>0.1 0.1 1.0</size>
            </box>
        </geometry></collision><visual name="link2_visual">
            
            <material>
                
            <lighting>1</lighting><script>
            <uri>file://media/materials/scripts/gazebo.material</uri>
            <name>Gazebo/Black</name>
        </script></material>
        <geometry>
            <box>
                <size>0.1 0.1 1.0</size>
            </box>
        </geometry></visual></link>
        <joint name="joint2" type="revolute">
            <parent>link2</parent>
            <child>link3</child>
            <pose>0 0 0.45 0 0 0</pose>
            <axis>
                <xyz>1 0 0</xyz>
                <dynamics>
                    <damping>0.5</damping>
                  </dynamics>
            </axis>
        </joint>
        <link name="link3">
            <pose relative_to="link2">0.1 0 -0.9 0 0 0</pose>
            <inertial>
                
            <mass>1.0</mass><inertia>
            <ixx>0.08416666666666667</ixx>
            <ixy>0</ixy>
            <ixz>0</ixz>
            <iyy>0.08416666666666667</iyy>
            <iyz>0</iyz>
            <izz>0.001666666666666667</izz>
        </inertia></inertial>
            
        <collision name="link3_collision">
            
        <geometry>
            <box>
                <size>0.1 0.1 1.0</size>
            </box>
        </geometry></collision><visual name="link3_visual">
            
            <material>
                
            <lighting>1</lighting><script>
            <uri>file://media/materials/scripts/gazebo.material</uri>
            <name>Gazebo/Orange</name>
        </script></material>
        <geometry>
            <box>
                <size>0.1 0.1 1.0</size>
            </box>
        </geometry></visual></link>
        <joint name="joint_camera" type="fixed">
            <parent>link3</parent>
            <child>camera_link</child>
            <pose>0 0 0 0 0 0</pose>
            <axis>
                <xyz>1 0 0</xyz>
            </axis>
        </joint>
        <link name="camera_link">
            <pose relative_to="link3">0.07500000000000001 0 -0.475 0 0 0</pose>
            <inertial>
                
            <mass>1e-05</mass><inertia>
            <ixx>4.1666666666666676e-09</ixx>
            <ixy>0</ixy>
            <ixz>0</ixz>
            <iyy>4.1666666666666676e-09</iyy>
            <iyz>0</iyz>
            <izz>4.1666666666666676e-09</izz>
        </inertia></inertial>
            
            
        <collision name="link3_collision">
            
        <geometry>
            <box>
                <size>0.05 0.05 0.05</size>
            </box>
        </geometry></collision><visual name="link3_visual">
            
            <material>
                
            <lighting>1</lighting><script>
            <uri>file://media/materials/scripts/gazebo.material</uri>
            <name>Gazebo/Red</name>
        </script></material>
        <geometry>
            <box>
                <size>0.05 0.05 0.05</size>
            </box>
        </geometry></visual><sensor type="camera" name="camera1">
            <update_rate>20.0</update_rate>
            <visualize>1</visualize>
            <!-- <pose>0.025 0 0 0 0 0</pose> -->
            <camera name="head">
                <horizontal_fov>0.8726646259971648</horizontal_fov>
                <image>
                    <width>640.0</width>
                    <height>480.0</height>
                    <format>R8G8B8</format>
                </image>
                <clip>
                    <near>0.02</near>
                    <far>300</far>
                </clip>
                <noise>
                    <type>gaussian</type>
                    <mean>0.0</mean>
                    <stddev>0.007</stddev>
                </noise>
            </camera>
        </sensor></link>
        <!-- <plugin name="joint_control" filename="libJointForcePlugin.so"/> -->
        <!-- <plugin name="joint_control" filename="libJointVelocityPlugin.so"/> -->
    </model>
</sdf>